Traceback (most recent call last):
  File "/opt/homebrew/lib/python3.11/site-packages/jupyter_cache/executors/utils.py", line 58, in single_nb_execution
    executenb(
  File "/opt/homebrew/lib/python3.11/site-packages/nbclient/client.py", line 1305, in execute
    return NotebookClient(nb=nb, resources=resources, km=km, **kwargs).execute()
           ^^^^^^^^^^^^^^^^^^^^^^^^^^^^^^^^^^^^^^^^^^^^^^^^^^^^^^^^^^^^^^^^^^^^^
  File "/Users/jon/Library/Python/3.11/lib/python/site-packages/jupyter_core/utils/__init__.py", line 166, in wrapped
    return loop.run_until_complete(inner)
           ^^^^^^^^^^^^^^^^^^^^^^^^^^^^^^
  File "/opt/homebrew/Cellar/python@3.11/3.11.10/Frameworks/Python.framework/Versions/3.11/lib/python3.11/asyncio/base_events.py", line 654, in run_until_complete
    return future.result()
           ^^^^^^^^^^^^^^^
  File "/opt/homebrew/lib/python3.11/site-packages/nbclient/client.py", line 705, in async_execute
    await self.async_execute_cell(
  File "/opt/homebrew/lib/python3.11/site-packages/nbclient/client.py", line 1058, in async_execute_cell
    await self._check_raise_for_error(cell, cell_index, exec_reply)
  File "/opt/homebrew/lib/python3.11/site-packages/nbclient/client.py", line 914, in _check_raise_for_error
    raise CellExecutionError.from_cell_and_msg(cell, exec_reply_content)
nbclient.exceptions.CellExecutionError: An error occurred while executing the following cell:
------------------
qyqpqr = quatMult(qy, qp)
------------------


[0;31m---------------------------------------------------------------------------[0m
[0;31mUFuncTypeError[0m                            Traceback (most recent call last)
Cell [0;32mIn[2], line 1[0m
[0;32m----> 1[0m qyqpqr [38;5;241m=[39m [43mquatMult[49m[43m([49m[43mqy[49m[43m,[49m[43m [49m[43mqp[49m[43m)[49m

Cell [0;32mIn[1], line 12[0m, in [0;36mquatMult[0;34m(q1, q2)[0m
[1;32m     11[0m [38;5;28;01mdef[39;00m [38;5;21mquatMult[39m(q1, q2):
[0;32m---> 12[0m     [38;5;28;01mreturn[39;00m np[38;5;241m.[39mappend(np[38;5;241m.[39marray(q1[[38;5;241m0[39m] [38;5;241m*[39m q2[[38;5;241m0[39m] [38;5;241m-[39m np[38;5;241m.[39mdot(q1[[38;5;241m1[39m:], q2[[38;5;241m1[39m:])), q1[[38;5;241m0[39m] [38;5;241m*[39m q2[[38;5;241m1[39m:] [38;5;241m+[39m q2[[38;5;241m0[39m] [38;5;241m*[39m q1[[38;5;241m1[39m:] [38;5;241m+[39m [43mnp[49m[38;5;241;43m.[39;49m[43mcross[49m[43m([49m[43mq1[49m[43m[[49m[38;5;241;43m1[39;49m[43m:[49m[43m][49m[43m,[49m[43m [49m[43mq2[49m[43m[[49m[38;5;241;43m1[39;49m[43m:[49m[43m][49m[43m)[49m)

File [0;32m/opt/homebrew/lib/python3.11/site-packages/numpy/core/numeric.py:1651[0m, in [0;36mcross[0;34m(a, b, axisa, axisb, axisc, axis)[0m
[1;32m   1649[0m cp0 [38;5;241m-[39m[38;5;241m=[39m tmp
[1;32m   1650[0m multiply(a2, b0, out[38;5;241m=[39mcp1)
[0;32m-> 1651[0m [43mmultiply[49m[43m([49m[43ma0[49m[43m,[49m[43m [49m[43mb2[49m[43m,[49m[43m [49m[43mout[49m[38;5;241;43m=[39;49m[43mtmp[49m[43m)[49m
[1;32m   1652[0m cp1 [38;5;241m-[39m[38;5;241m=[39m tmp
[1;32m   1653[0m multiply(a0, b1, out[38;5;241m=[39mcp2)

[0;31mUFuncTypeError[0m: Cannot cast ufunc 'multiply' output from dtype('O') to dtype('int64') with casting rule 'same_kind'

