Traceback (most recent call last):
  File "/Users/55093290/anaconda3/lib/python3.11/site-packages/jupyter_cache/executors/utils.py", line 58, in single_nb_execution
    executenb(
  File "/Users/55093290/anaconda3/lib/python3.11/site-packages/nbclient/client.py", line 1204, in execute
    return NotebookClient(nb=nb, resources=resources, km=km, **kwargs).execute()
           ^^^^^^^^^^^^^^^^^^^^^^^^^^^^^^^^^^^^^^^^^^^^^^^^^^^^^^^^^^^^^^^^^^^^^
  File "/Users/55093290/anaconda3/lib/python3.11/site-packages/nbclient/util.py", line 84, in wrapped
    return just_run(coro(*args, **kwargs))
           ^^^^^^^^^^^^^^^^^^^^^^^^^^^^^^^
  File "/Users/55093290/anaconda3/lib/python3.11/site-packages/nbclient/util.py", line 62, in just_run
    return loop.run_until_complete(coro)
           ^^^^^^^^^^^^^^^^^^^^^^^^^^^^^
  File "/Users/55093290/anaconda3/lib/python3.11/asyncio/base_events.py", line 653, in run_until_complete
    return future.result()
           ^^^^^^^^^^^^^^^
  File "/Users/55093290/anaconda3/lib/python3.11/site-packages/nbclient/client.py", line 663, in async_execute
    await self.async_execute_cell(
  File "/Users/55093290/anaconda3/lib/python3.11/site-packages/nbclient/client.py", line 965, in async_execute_cell
    await self._check_raise_for_error(cell, cell_index, exec_reply)
  File "/Users/55093290/anaconda3/lib/python3.11/site-packages/nbclient/client.py", line 862, in _check_raise_for_error
    raise CellExecutionError.from_cell_and_msg(cell, exec_reply_content)
nbclient.exceptions.CellExecutionError: An error occurred while executing the following cell:
------------------
qyqpqr = quatMult(qy, qp)
------------------

[0;31m---------------------------------------------------------------------------[0m
[0;31mUFuncTypeError[0m                            Traceback (most recent call last)
Cell [0;32mIn[2], line 1[0m
[0;32m----> 1[0m qyqpqr [38;5;241m=[39m quatMult(qy, qp)

Cell [0;32mIn[1], line 12[0m, in [0;36mquatMult[0;34m(q1, q2)[0m
[1;32m     11[0m [38;5;28;01mdef[39;00m [38;5;21mquatMult[39m(q1, q2):
[0;32m---> 12[0m     [38;5;28;01mreturn[39;00m np[38;5;241m.[39mappend(np[38;5;241m.[39marray(q1[[38;5;241m0[39m] [38;5;241m*[39m q2[[38;5;241m0[39m] [38;5;241m-[39m np[38;5;241m.[39mdot(q1[[38;5;241m1[39m:], q2[[38;5;241m1[39m:])), q1[[38;5;241m0[39m] [38;5;241m*[39m q2[[38;5;241m1[39m:] [38;5;241m+[39m q2[[38;5;241m0[39m] [38;5;241m*[39m q1[[38;5;241m1[39m:] [38;5;241m+[39m np[38;5;241m.[39mcross(q1[[38;5;241m1[39m:], q2[[38;5;241m1[39m:]))

File [0;32m<__array_function__ internals>:200[0m, in [0;36mcross[0;34m(*args, **kwargs)[0m

File [0;32m~/anaconda3/lib/python3.11/site-packages/numpy/core/numeric.py:1669[0m, in [0;36mcross[0;34m(a, b, axisa, axisb, axisc, axis)[0m
[1;32m   1667[0m cp0 [38;5;241m-[39m[38;5;241m=[39m tmp
[1;32m   1668[0m multiply(a2, b0, out[38;5;241m=[39mcp1)
[0;32m-> 1669[0m multiply(a0, b2, out[38;5;241m=[39mtmp)
[1;32m   1670[0m cp1 [38;5;241m-[39m[38;5;241m=[39m tmp
[1;32m   1671[0m multiply(a0, b1, out[38;5;241m=[39mcp2)

[0;31mUFuncTypeError[0m: Cannot cast ufunc 'multiply' output from dtype('O') to dtype('int64') with casting rule 'same_kind'
UFuncTypeError: Cannot cast ufunc 'multiply' output from dtype('O') to dtype('int64') with casting rule 'same_kind'

